test_0 (__main__.lab1a.test_0)
[Lab 1] - [Investigation 3] - [Part 2] - printing - Test for file creation: ./lab1a.py ... ok
test_a (__main__.lab1a.test_a)
[Lab 1] - [Investigation 3] - [Part 2] - printing - Test for errors running: ./lab1a.py ... /usr/lib/python3.12/subprocess.py:822: ResourceWarning: unclosed file <_io.TextIOWrapper name=3 encoding='UTF-8'>
  _cleanup()
ResourceWarning: Enable tracemalloc to get the object allocation traceback
ok
test_a1 (__main__.lab1a.test_a1)
[Lab 1] - [Investigation 3] - [Part 2] - printing - Test for correct shebang line: ./lab1a.py ... FAIL

======================================================================
FAIL: test_a1 (__main__.lab1a.test_a1)
[Lab 1] - [Investigation 3] - [Part 2] - printing - Test for correct shebang line: ./lab1a.py
----------------------------------------------------------------------
Traceback (most recent call last):
  File "/home/fraj/ops445/lab1/./CheckLab1.py", line 79, in test_a1
    self.assertEqual(first_line, '#!/usr/bin/env python3\n', msg=error_output)
AssertionError: "print('hello world')\n" != '#!/usr/bin/env python3\n'
- print('hello world')
+ #!/usr/bin/env python3
 : your program does not have a shebang line(HINT: what should the first line contain)

----------------------------------------------------------------------
Ran 3 tests in 0.026s

FAILED (failures=1)
OPS445 Lab Report - System Information for running ./CheckLab1.py
=================================================================
    User login name: fraj
    Git Email: rajperfahad@gmail.com
    Linux system name: fraj-virtual-machine
    Python executable: /usr/bin/python3
    Python version:  3.12.3 (main, Feb  4 2025, 14:48:35) [GCC 13.3.0]
    OS Platform: linux
    Working Directory: /home/fraj/ops445/lab1
    Start at: Mon May 26 20:04:21 2025
=================================================================
